
2023-07-30 18:31:51 - ERROR - Uncaught exception
Traceback (most recent call last):
  File "C:\Users\Elaman\PycharmProjects\pythonProject\rdy\main.py", line 292, in on_click_ready
    start(self.student_ids[widget.objectName()]["login"],
  File "C:\Users\Elaman\PycharmProjects\pythonProject\rdy\script_bot.py", line 26, in start
    time.sleep(10)
KeyboardInterrupt

2023-08-13 04:39:45 - ERROR - Uncaught exception
Traceback (most recent call last):
  File "C:\Users\Elaman\PycharmProjects\auto_bot_qt\venv\lib\site-packages\pandas\compat\_optional.py", line 142, in import_optional_dependency
    module = importlib.import_module(name)
  File "C:\Users\Elaman\AppData\Local\Programs\Python\Python310\lib\importlib\__init__.py", line 126, in import_module
    return _bootstrap._gcd_import(name[level:], package, level)
  File "<frozen importlib._bootstrap>", line 1050, in _gcd_import
  File "<frozen importlib._bootstrap>", line 1027, in _find_and_load
  File "<frozen importlib._bootstrap>", line 1004, in _find_and_load_unlocked
ModuleNotFoundError: No module named 'openpyxl'

During handling of the above exception, another exception occurred:

Traceback (most recent call last):
  File "C:\Users\Elaman\PycharmProjects\auto_bot_qt\rdy\main.py", line 94, in init_ui
    self.dict_semestr_lesson, self.students = data(True, progress_dialog.update_progress)
  File "C:\Users\Elaman\PycharmProjects\auto_bot_qt\rdy\parsing.py", line 64, in data
    dict_semestr_lesson[dir_] = {
  File "C:\Users\Elaman\PycharmProjects\auto_bot_qt\rdy\parsing.py", line 65, in <dictcomp>
    folder_group: {
  File "C:\Users\Elaman\PycharmProjects\auto_bot_qt\rdy\parsing.py", line 66, in <dictcomp>
    item: generate(os.path.join(path, dir_, folder_group, f"{item}.xlsx"))
  File "C:\Users\Elaman\PycharmProjects\auto_bot_qt\rdy\parsing.py", line 28, in generate
    df = pd.read_excel(item, header=None, skiprows=1, usecols=[0, 1, 2])
  File "C:\Users\Elaman\PycharmProjects\auto_bot_qt\venv\lib\site-packages\pandas\io\excel\_base.py", line 478, in read_excel
    io = ExcelFile(io, storage_options=storage_options, engine=engine)
  File "C:\Users\Elaman\PycharmProjects\auto_bot_qt\venv\lib\site-packages\pandas\io\excel\_base.py", line 1513, in __init__
    self._reader = self._engines[engine](self._io, storage_options=storage_options)
  File "C:\Users\Elaman\PycharmProjects\auto_bot_qt\venv\lib\site-packages\pandas\io\excel\_openpyxl.py", line 548, in __init__
    import_optional_dependency("openpyxl")
  File "C:\Users\Elaman\PycharmProjects\auto_bot_qt\venv\lib\site-packages\pandas\compat\_optional.py", line 145, in import_optional_dependency
    raise ImportError(msg)
ImportError: Missing optional dependency 'openpyxl'.  Use pip or conda to install openpyxl.

2023-08-13 04:39:46 - ERROR - Uncaught exception
Traceback (most recent call last):
  File "C:\Users\Elaman\PycharmProjects\auto_bot_qt\rdy\main.py", line 155, in create_tabs
    for semestr in self.dict_semestr_lesson:
TypeError: 'NoneType' object is not iterable

2023-08-14 23:26:39 - ERROR - Uncaught exception
Traceback (most recent call last):
  File "C:\Users\Elaman\PycharmProjects\auto_bot_qt\venv\lib\site-packages\pandas\compat\_optional.py", line 142, in import_optional_dependency
    module = importlib.import_module(name)
  File "C:\Users\Elaman\AppData\Local\Programs\Python\Python310\lib\importlib\__init__.py", line 126, in import_module
    return _bootstrap._gcd_import(name[level:], package, level)
  File "<frozen importlib._bootstrap>", line 1050, in _gcd_import
  File "<frozen importlib._bootstrap>", line 1027, in _find_and_load
  File "<frozen importlib._bootstrap>", line 1004, in _find_and_load_unlocked
ModuleNotFoundError: No module named 'openpyxl'

During handling of the above exception, another exception occurred:

Traceback (most recent call last):
  File "C:\Users\Elaman\PycharmProjects\auto_bot_qt\rdy\main.py", line 94, in init_ui
    self.dict_semestr_lesson, self.students = data(True, progress_dialog.update_progress)
  File "C:\Users\Elaman\PycharmProjects\auto_bot_qt\rdy\parsing.py", line 64, in data
    dict_semestr_lesson[dir_] = {
  File "C:\Users\Elaman\PycharmProjects\auto_bot_qt\rdy\parsing.py", line 65, in <dictcomp>
    folder_group: {
  File "C:\Users\Elaman\PycharmProjects\auto_bot_qt\rdy\parsing.py", line 66, in <dictcomp>
    item: generate(os.path.join(path, dir_, folder_group, f"{item}.xlsx"))
  File "C:\Users\Elaman\PycharmProjects\auto_bot_qt\rdy\parsing.py", line 28, in generate
    df = pd.read_excel(item, header=None, skiprows=1, usecols=[0, 1, 2])
  File "C:\Users\Elaman\PycharmProjects\auto_bot_qt\venv\lib\site-packages\pandas\io\excel\_base.py", line 478, in read_excel
    io = ExcelFile(io, storage_options=storage_options, engine=engine)
  File "C:\Users\Elaman\PycharmProjects\auto_bot_qt\venv\lib\site-packages\pandas\io\excel\_base.py", line 1513, in __init__
    self._reader = self._engines[engine](self._io, storage_options=storage_options)
  File "C:\Users\Elaman\PycharmProjects\auto_bot_qt\venv\lib\site-packages\pandas\io\excel\_openpyxl.py", line 548, in __init__
    import_optional_dependency("openpyxl")
  File "C:\Users\Elaman\PycharmProjects\auto_bot_qt\venv\lib\site-packages\pandas\compat\_optional.py", line 145, in import_optional_dependency
    raise ImportError(msg)
ImportError: Missing optional dependency 'openpyxl'.  Use pip or conda to install openpyxl.

2023-08-14 23:26:41 - ERROR - Uncaught exception
Traceback (most recent call last):
  File "C:\Users\Elaman\PycharmProjects\auto_bot_qt\rdy\main.py", line 155, in create_tabs
    for semestr in self.dict_semestr_lesson:
TypeError: 'NoneType' object is not iterable

2023-08-15 00:09:26 - ERROR - Uncaught exception
Traceback (most recent call last):
  File "C:\Users\Elaman\PycharmProjects\auto_bot_qt\rdy\main.py", line 273, in open_dialog
    button_all.clicked.connect()
TypeError: connect() missing required argument 'slot' (pos 1)

2023-08-15 00:09:29 - ERROR - Uncaught exception
Traceback (most recent call last):
  File "C:\Users\Elaman\PycharmProjects\auto_bot_qt\rdy\main.py", line 273, in open_dialog
    button_all.clicked.connect()
TypeError: connect() missing required argument 'slot' (pos 1)

2023-08-20 20:14:37 - ERROR - Uncaught exception
Traceback (most recent call last):
  File "C:\Users\Elaman\PycharmProjects\auto_bot_qt\rdy\main.py", line 259, in open_dialog
    self.current_lesson = self.lessons[button_name]
KeyError: 'Тест 1 семестр'

2023-08-30 18:32:33 - ERROR - Uncaught exception
Traceback (most recent call last):
  File "C:\Users\Elaman\AppData\Local\Programs\Python\Python310\lib\socket.py", line 705, in readinto
    return self._sock.recv_into(b)
ConnectionResetError: [WinError 10054] Удаленный хост принудительно разорвал существующее подключение

During handling of the above exception, another exception occurred:

Traceback (most recent call last):
  File "C:\Users\Elaman\PycharmProjects\auto_bot_qt\rdy\main.py", line 308, in on_click_ready
    start(self.students[widget.objectName()], self.current_lesson,
  File "C:\Users\Elaman\PycharmProjects\auto_bot_qt\rdy\script_bot.py", line 18, in start
    driver.get(url="https://dot.omgups.ru/login/index.php")
  File "C:\Users\Elaman\PycharmProjects\auto_bot_qt\venv\lib\site-packages\selenium\webdriver\remote\webdriver.py", line 354, in get
    self.execute(Command.GET, {"url": url})
  File "C:\Users\Elaman\PycharmProjects\auto_bot_qt\venv\lib\site-packages\selenium\webdriver\remote\webdriver.py", line 343, in execute
    response = self.command_executor.execute(driver_command, params)
  File "C:\Users\Elaman\PycharmProjects\auto_bot_qt\venv\lib\site-packages\selenium\webdriver\remote\remote_connection.py", line 291, in execute
    return self._request(command_info[0], url, body=data)
  File "C:\Users\Elaman\PycharmProjects\auto_bot_qt\venv\lib\site-packages\selenium\webdriver\remote\remote_connection.py", line 312, in _request
    response = self._conn.request(method, url, body=body, headers=headers)
  File "C:\Users\Elaman\PycharmProjects\auto_bot_qt\venv\lib\site-packages\urllib3\_request_methods.py", line 118, in request
    return self.request_encode_body(
  File "C:\Users\Elaman\PycharmProjects\auto_bot_qt\venv\lib\site-packages\urllib3\_request_methods.py", line 217, in request_encode_body
    return self.urlopen(method, url, **extra_kw)
  File "C:\Users\Elaman\PycharmProjects\auto_bot_qt\venv\lib\site-packages\urllib3\poolmanager.py", line 443, in urlopen
    response = conn.urlopen(method, u.request_uri, **kw)
  File "C:\Users\Elaman\PycharmProjects\auto_bot_qt\venv\lib\site-packages\urllib3\connectionpool.py", line 790, in urlopen
    response = self._make_request(
  File "C:\Users\Elaman\PycharmProjects\auto_bot_qt\venv\lib\site-packages\urllib3\connectionpool.py", line 536, in _make_request
    response = conn.getresponse()
  File "C:\Users\Elaman\PycharmProjects\auto_bot_qt\venv\lib\site-packages\urllib3\connection.py", line 461, in getresponse
    httplib_response = super().getresponse()
  File "C:\Users\Elaman\AppData\Local\Programs\Python\Python310\lib\http\client.py", line 1368, in getresponse
    response.begin()
  File "C:\Users\Elaman\AppData\Local\Programs\Python\Python310\lib\http\client.py", line 317, in begin
    version, status, reason = self._read_status()
  File "C:\Users\Elaman\AppData\Local\Programs\Python\Python310\lib\http\client.py", line 278, in _read_status
    line = str(self.fp.readline(_MAXLINE + 1), "iso-8859-1")
  File "C:\Users\Elaman\AppData\Local\Programs\Python\Python310\lib\socket.py", line 705, in readinto
    return self._sock.recv_into(b)
KeyboardInterrupt

2023-08-30 22:33:53 - ERROR - Uncaught exception
Traceback (most recent call last):
  File "C:\Users\Elaman\PycharmProjects\auto_bot_qt\rdy\main.py", line 285, in open_dialog
    dialog.exec_()
KeyboardInterrupt

2023-08-31 13:46:55 - ERROR - Uncaught exception
Traceback (most recent call last):
  File "C:\Users\Elaman\PycharmProjects\auto_bot_qt\rdy\script_bot.py", line 64, in start
    button_next = driver.find_element(by=By.CSS_SELECTOR, value="input[type='submit'][name='next']")
  File "C:\Users\Elaman\PycharmProjects\auto_bot_qt\venv\lib\site-packages\selenium\webdriver\remote\webdriver.py", line 739, in find_element
    return self.execute(Command.FIND_ELEMENT, {"using": by, "value": value})["value"]
  File "C:\Users\Elaman\PycharmProjects\auto_bot_qt\venv\lib\site-packages\selenium\webdriver\remote\webdriver.py", line 345, in execute
    self.error_handler.check_response(response)
  File "C:\Users\Elaman\PycharmProjects\auto_bot_qt\venv\lib\site-packages\selenium\webdriver\remote\errorhandler.py", line 229, in check_response
    raise exception_class(message, screen, stacktrace)
selenium.common.exceptions.NoSuchElementException: Message: no such element: Unable to locate element: {"method":"css selector","selector":"input[type='submit'][name='next']"}
  (Session info: chrome=116.0.5845.141); For documentation on this error, please visit: https://www.selenium.dev/documentation/webdriver/troubleshooting/errors#no-such-element-exception
Stacktrace:
	GetHandleVerifier [0x00007FF7528F52A2+57122]
	(No symbol) [0x00007FF75286EA92]
	(No symbol) [0x00007FF75273E3AB]
	(No symbol) [0x00007FF752777D3E]
	(No symbol) [0x00007FF752777E2C]
	(No symbol) [0x00007FF7527B0B67]
	(No symbol) [0x00007FF75279701F]
	(No symbol) [0x00007FF7527AEB82]
	(No symbol) [0x00007FF752796DB3]
	(No symbol) [0x00007FF75276D2B1]
	(No symbol) [0x00007FF75276E494]
	GetHandleVerifier [0x00007FF752B9EF82+2849794]
	GetHandleVerifier [0x00007FF752BF1D24+3189156]
	GetHandleVerifier [0x00007FF752BEACAF+3160367]
	GetHandleVerifier [0x00007FF752986D06+653702]
	(No symbol) [0x00007FF75287A208]
	(No symbol) [0x00007FF7528762C4]
	(No symbol) [0x00007FF7528763F6]
	(No symbol) [0x00007FF7528667A3]
	BaseThreadInitThunk [0x00007FFEFED47614+20]
	RtlUserThreadStart [0x00007FFEFEE826B1+33]


During handling of the above exception, another exception occurred:

Traceback (most recent call last):
  File "C:\Users\Elaman\PycharmProjects\auto_bot_qt\rdy\main.py", line 313, in on_click_ready
    start(self.students[widget.objectName()], answers_,
  File "C:\Users\Elaman\PycharmProjects\auto_bot_qt\rdy\script_bot.py", line 91, in start
    time.sleep(100)
KeyboardInterrupt

2023-09-01 11:26:46 - ERROR - Uncaught exception
Traceback (most recent call last):
  File "C:\Users\Elaman\PycharmProjects\auto_bot_qt\rdy\main.py", line 313, in on_click_ready
    start(self.students[widget.objectName()], answers_,
  File "C:\Users\Elaman\PycharmProjects\auto_bot_qt\rdy\script_bot.py", line 101, in start
    time.sleep(time_in_seconds / 2)
KeyboardInterrupt

2023-09-01 12:39:58 - ERROR - Uncaught exception
Traceback (most recent call last):
  File "C:\Users\Elaman\PycharmProjects\auto_bot_qt\rdy\main.py", line 313, in on_click_ready
    start(self.students[widget.objectName()], answers_,
  File "C:\Users\Elaman\PycharmProjects\auto_bot_qt\rdy\script_bot.py", line 108, in start
    time.sleep(time_in_seconds / 2)
KeyboardInterrupt

2023-09-03 15:04:24 - ERROR - Uncaught exception
Traceback (most recent call last):
  File "C:\Users\Elaman\PycharmProjects\auto_bot_qt\rdy\main.py", line 313, in on_click_ready
    start(self.students[widget.objectName()], answers_,
  File "C:\Users\Elaman\PycharmProjects\auto_bot_qt\rdy\script_bot.py", line 56, in start
    time.sleep(10)
KeyboardInterrupt

2023-09-03 15:06:25 - ERROR - Uncaught exception
Traceback (most recent call last):
  File "C:\Users\Elaman\PycharmProjects\auto_bot_qt\rdy\main.py", line 313, in on_click_ready
    start(self.students[widget.objectName()], answers_,
  File "C:\Users\Elaman\PycharmProjects\auto_bot_qt\rdy\script_bot.py", line 109, in start
    time.sleep(time_in_seconds / 2)
KeyboardInterrupt

2023-09-03 15:10:06 - ERROR - Uncaught exception
Traceback (most recent call last):
  File "C:\Users\Elaman\PycharmProjects\auto_bot_qt\rdy\main.py", line 313, in on_click_ready
    start(self.students[widget.objectName()], answers_,
  File "C:\Users\Elaman\PycharmProjects\auto_bot_qt\rdy\script_bot.py", line 110, in start
    time.sleep(time_in_seconds / 2)
KeyboardInterrupt

2023-09-03 15:13:17 - ERROR - Uncaught exception
Traceback (most recent call last):
  File "C:\Users\Elaman\PycharmProjects\auto_bot_qt\rdy\main.py", line 313, in on_click_ready
    start(self.students[widget.objectName()], answers_,
  File "C:\Users\Elaman\PycharmProjects\auto_bot_qt\rdy\script_bot.py", line 110, in start
    time.sleep(time_in_seconds / 2)
KeyboardInterrupt

2023-09-03 15:34:14 - ERROR - Uncaught exception
Traceback (most recent call last):
  File "C:\Users\Elaman\PycharmProjects\auto_bot_qt\rdy\main.py", line 313, in on_click_ready
    start(self.students[widget.objectName()], answers_,
  File "C:\Users\Elaman\PycharmProjects\auto_bot_qt\rdy\script_bot.py", line 111, in start
    time.sleep(time_in_seconds / 2)
KeyboardInterrupt
