
2024-09-04 11:14:02 - ERROR - Uncaught exception
Traceback (most recent call last):
  File "C:\Users\Elaman\PycharmProjects\grade_checker\venv\Lib\site-packages\urllib3\connection.py", line 203, in _new_conn
    sock = connection.create_connection(
           ^^^^^^^^^^^^^^^^^^^^^^^^^^^^^
  File "C:\Users\Elaman\PycharmProjects\grade_checker\venv\Lib\site-packages\urllib3\util\connection.py", line 60, in create_connection
    for res in socket.getaddrinfo(host, port, family, socket.SOCK_STREAM):
               ^^^^^^^^^^^^^^^^^^^^^^^^^^^^^^^^^^^^^^^^^^^^^^^^^^^^^^^^^^
  File "C:\Users\Elaman\AppData\Local\Programs\Python\Python311\Lib\socket.py", line 962, in getaddrinfo
    for res in _socket.getaddrinfo(host, port, family, type, proto, flags):
               ^^^^^^^^^^^^^^^^^^^^^^^^^^^^^^^^^^^^^^^^^^^^^^^^^^^^^^^^^^^
socket.gaierror: [Errno 11001] getaddrinfo failed

The above exception was the direct cause of the following exception:

Traceback (most recent call last):
  File "C:\Users\Elaman\PycharmProjects\grade_checker\venv\Lib\site-packages\urllib3\connectionpool.py", line 790, in urlopen
    response = self._make_request(
               ^^^^^^^^^^^^^^^^^^^
  File "C:\Users\Elaman\PycharmProjects\grade_checker\venv\Lib\site-packages\urllib3\connectionpool.py", line 491, in _make_request
    raise new_e
  File "C:\Users\Elaman\PycharmProjects\grade_checker\venv\Lib\site-packages\urllib3\connectionpool.py", line 467, in _make_request
    self._validate_conn(conn)
  File "C:\Users\Elaman\PycharmProjects\grade_checker\venv\Lib\site-packages\urllib3\connectionpool.py", line 1096, in _validate_conn
    conn.connect()
  File "C:\Users\Elaman\PycharmProjects\grade_checker\venv\Lib\site-packages\urllib3\connection.py", line 611, in connect
    self.sock = sock = self._new_conn()
                       ^^^^^^^^^^^^^^^^
  File "C:\Users\Elaman\PycharmProjects\grade_checker\venv\Lib\site-packages\urllib3\connection.py", line 210, in _new_conn
    raise NameResolutionError(self.host, self, e) from e
urllib3.exceptions.NameResolutionError: <urllib3.connection.HTTPSConnection object at 0x0000022471453090>: Failed to resolve 'googlechromelabs.github.io' ([Errno 11001] getaddrinfo failed)

The above exception was the direct cause of the following exception:

Traceback (most recent call last):
  File "C:\Users\Elaman\PycharmProjects\grade_checker\venv\Lib\site-packages\requests\adapters.py", line 486, in send
    resp = conn.urlopen(
           ^^^^^^^^^^^^^
  File "C:\Users\Elaman\PycharmProjects\grade_checker\venv\Lib\site-packages\urllib3\connectionpool.py", line 844, in urlopen
    retries = retries.increment(
              ^^^^^^^^^^^^^^^^^^
  File "C:\Users\Elaman\PycharmProjects\grade_checker\venv\Lib\site-packages\urllib3\util\retry.py", line 515, in increment
    raise MaxRetryError(_pool, url, reason) from reason  # type: ignore[arg-type]
    ^^^^^^^^^^^^^^^^^^^^^^^^^^^^^^^^^^^^^^^^^^^^^^^^^^^
urllib3.exceptions.MaxRetryError: HTTPSConnectionPool(host='googlechromelabs.github.io', port=443): Max retries exceeded with url: /chrome-for-testing/latest-patch-versions-per-build.json (Caused by NameResolutionError("<urllib3.connection.HTTPSConnection object at 0x0000022471453090>: Failed to resolve 'googlechromelabs.github.io' ([Errno 11001] getaddrinfo failed)"))

During handling of the above exception, another exception occurred:

Traceback (most recent call last):
  File "C:\Users\Elaman\PycharmProjects\grade_checker\venv\Lib\site-packages\webdriver_manager\core\http.py", line 32, in get
    resp = requests.get(
           ^^^^^^^^^^^^^
  File "C:\Users\Elaman\PycharmProjects\grade_checker\venv\Lib\site-packages\requests\api.py", line 73, in get
    return request("get", url, params=params, **kwargs)
           ^^^^^^^^^^^^^^^^^^^^^^^^^^^^^^^^^^^^^^^^^^^^
  File "C:\Users\Elaman\PycharmProjects\grade_checker\venv\Lib\site-packages\requests\api.py", line 59, in request
    return session.request(method=method, url=url, **kwargs)
           ^^^^^^^^^^^^^^^^^^^^^^^^^^^^^^^^^^^^^^^^^^^^^^^^^
  File "C:\Users\Elaman\PycharmProjects\grade_checker\venv\Lib\site-packages\requests\sessions.py", line 589, in request
    resp = self.send(prep, **send_kwargs)
           ^^^^^^^^^^^^^^^^^^^^^^^^^^^^^^
  File "C:\Users\Elaman\PycharmProjects\grade_checker\venv\Lib\site-packages\requests\sessions.py", line 703, in send
    r = adapter.send(request, **kwargs)
        ^^^^^^^^^^^^^^^^^^^^^^^^^^^^^^^
  File "C:\Users\Elaman\PycharmProjects\grade_checker\venv\Lib\site-packages\requests\adapters.py", line 519, in send
    raise ConnectionError(e, request=request)
requests.exceptions.ConnectionError: HTTPSConnectionPool(host='googlechromelabs.github.io', port=443): Max retries exceeded with url: /chrome-for-testing/latest-patch-versions-per-build.json (Caused by NameResolutionError("<urllib3.connection.HTTPSConnection object at 0x0000022471453090>: Failed to resolve 'googlechromelabs.github.io' ([Errno 11001] getaddrinfo failed)"))

During handling of the above exception, another exception occurred:

Traceback (most recent call last):
  File "C:\Users\Elaman\PycharmProjects\grade_checker\main.py", line 13, in <module>
    mainWindow = Config()
                 ^^^^^^^^
  File "C:\Users\Elaman\PycharmProjects\grade_checker\Config.py", line 28, in __init__
    chrome_install = ChromeDriverManager().install()
                     ^^^^^^^^^^^^^^^^^^^^^^^^^^^^^^^
  File "C:\Users\Elaman\PycharmProjects\grade_checker\venv\Lib\site-packages\webdriver_manager\chrome.py", line 40, in install
    driver_path = self._get_driver_binary_path(self.driver)
                  ^^^^^^^^^^^^^^^^^^^^^^^^^^^^^^^^^^^^^^^^^
  File "C:\Users\Elaman\PycharmProjects\grade_checker\venv\Lib\site-packages\webdriver_manager\core\manager.py", line 35, in _get_driver_binary_path
    binary_path = self._cache_manager.find_driver(driver)
                  ^^^^^^^^^^^^^^^^^^^^^^^^^^^^^^^^^^^^^^^
  File "C:\Users\Elaman\PycharmProjects\grade_checker\venv\Lib\site-packages\webdriver_manager\core\driver_cache.py", line 107, in find_driver
    driver_version = self.get_cache_key_driver_version(driver)
                     ^^^^^^^^^^^^^^^^^^^^^^^^^^^^^^^^^^^^^^^^^
  File "C:\Users\Elaman\PycharmProjects\grade_checker\venv\Lib\site-packages\webdriver_manager\core\driver_cache.py", line 154, in get_cache_key_driver_version
    return driver.get_driver_version_to_download()
           ^^^^^^^^^^^^^^^^^^^^^^^^^^^^^^^^^^^^^^^
  File "C:\Users\Elaman\PycharmProjects\grade_checker\venv\Lib\site-packages\webdriver_manager\core\driver.py", line 48, in get_driver_version_to_download
    return self.get_latest_release_version()
           ^^^^^^^^^^^^^^^^^^^^^^^^^^^^^^^^^
  File "C:\Users\Elaman\PycharmProjects\grade_checker\venv\Lib\site-packages\webdriver_manager\drivers\chrome.py", line 59, in get_latest_release_version
    response = self._http_client.get(url)
               ^^^^^^^^^^^^^^^^^^^^^^^^^^
  File "C:\Users\Elaman\PycharmProjects\grade_checker\venv\Lib\site-packages\webdriver_manager\core\http.py", line 35, in get
    raise exceptions.ConnectionError(f"Could not reach host. Are you offline?")
requests.exceptions.ConnectionError: Could not reach host. Are you offline?

2024-09-04 11:14:09 - ERROR - Uncaught exception
Traceback (most recent call last):
  File "C:\Users\Elaman\PycharmProjects\grade_checker\venv\Lib\site-packages\urllib3\connection.py", line 203, in _new_conn
    sock = connection.create_connection(
           ^^^^^^^^^^^^^^^^^^^^^^^^^^^^^
  File "C:\Users\Elaman\PycharmProjects\grade_checker\venv\Lib\site-packages\urllib3\util\connection.py", line 60, in create_connection
    for res in socket.getaddrinfo(host, port, family, socket.SOCK_STREAM):
               ^^^^^^^^^^^^^^^^^^^^^^^^^^^^^^^^^^^^^^^^^^^^^^^^^^^^^^^^^^
  File "C:\Users\Elaman\AppData\Local\Programs\Python\Python311\Lib\socket.py", line 962, in getaddrinfo
    for res in _socket.getaddrinfo(host, port, family, type, proto, flags):
               ^^^^^^^^^^^^^^^^^^^^^^^^^^^^^^^^^^^^^^^^^^^^^^^^^^^^^^^^^^^
socket.gaierror: [Errno 11001] getaddrinfo failed

The above exception was the direct cause of the following exception:

Traceback (most recent call last):
  File "C:\Users\Elaman\PycharmProjects\grade_checker\venv\Lib\site-packages\urllib3\connectionpool.py", line 790, in urlopen
    response = self._make_request(
               ^^^^^^^^^^^^^^^^^^^
  File "C:\Users\Elaman\PycharmProjects\grade_checker\venv\Lib\site-packages\urllib3\connectionpool.py", line 491, in _make_request
    raise new_e
  File "C:\Users\Elaman\PycharmProjects\grade_checker\venv\Lib\site-packages\urllib3\connectionpool.py", line 467, in _make_request
    self._validate_conn(conn)
  File "C:\Users\Elaman\PycharmProjects\grade_checker\venv\Lib\site-packages\urllib3\connectionpool.py", line 1096, in _validate_conn
    conn.connect()
  File "C:\Users\Elaman\PycharmProjects\grade_checker\venv\Lib\site-packages\urllib3\connection.py", line 611, in connect
    self.sock = sock = self._new_conn()
                       ^^^^^^^^^^^^^^^^
  File "C:\Users\Elaman\PycharmProjects\grade_checker\venv\Lib\site-packages\urllib3\connection.py", line 210, in _new_conn
    raise NameResolutionError(self.host, self, e) from e
urllib3.exceptions.NameResolutionError: <urllib3.connection.HTTPSConnection object at 0x00000210139C3090>: Failed to resolve 'googlechromelabs.github.io' ([Errno 11001] getaddrinfo failed)

The above exception was the direct cause of the following exception:

Traceback (most recent call last):
  File "C:\Users\Elaman\PycharmProjects\grade_checker\venv\Lib\site-packages\requests\adapters.py", line 486, in send
    resp = conn.urlopen(
           ^^^^^^^^^^^^^
  File "C:\Users\Elaman\PycharmProjects\grade_checker\venv\Lib\site-packages\urllib3\connectionpool.py", line 844, in urlopen
    retries = retries.increment(
              ^^^^^^^^^^^^^^^^^^
  File "C:\Users\Elaman\PycharmProjects\grade_checker\venv\Lib\site-packages\urllib3\util\retry.py", line 515, in increment
    raise MaxRetryError(_pool, url, reason) from reason  # type: ignore[arg-type]
    ^^^^^^^^^^^^^^^^^^^^^^^^^^^^^^^^^^^^^^^^^^^^^^^^^^^
urllib3.exceptions.MaxRetryError: HTTPSConnectionPool(host='googlechromelabs.github.io', port=443): Max retries exceeded with url: /chrome-for-testing/latest-patch-versions-per-build.json (Caused by NameResolutionError("<urllib3.connection.HTTPSConnection object at 0x00000210139C3090>: Failed to resolve 'googlechromelabs.github.io' ([Errno 11001] getaddrinfo failed)"))

During handling of the above exception, another exception occurred:

Traceback (most recent call last):
  File "C:\Users\Elaman\PycharmProjects\grade_checker\venv\Lib\site-packages\webdriver_manager\core\http.py", line 32, in get
    resp = requests.get(
           ^^^^^^^^^^^^^
  File "C:\Users\Elaman\PycharmProjects\grade_checker\venv\Lib\site-packages\requests\api.py", line 73, in get
    return request("get", url, params=params, **kwargs)
           ^^^^^^^^^^^^^^^^^^^^^^^^^^^^^^^^^^^^^^^^^^^^
  File "C:\Users\Elaman\PycharmProjects\grade_checker\venv\Lib\site-packages\requests\api.py", line 59, in request
    return session.request(method=method, url=url, **kwargs)
           ^^^^^^^^^^^^^^^^^^^^^^^^^^^^^^^^^^^^^^^^^^^^^^^^^
  File "C:\Users\Elaman\PycharmProjects\grade_checker\venv\Lib\site-packages\requests\sessions.py", line 589, in request
    resp = self.send(prep, **send_kwargs)
           ^^^^^^^^^^^^^^^^^^^^^^^^^^^^^^
  File "C:\Users\Elaman\PycharmProjects\grade_checker\venv\Lib\site-packages\requests\sessions.py", line 703, in send
    r = adapter.send(request, **kwargs)
        ^^^^^^^^^^^^^^^^^^^^^^^^^^^^^^^
  File "C:\Users\Elaman\PycharmProjects\grade_checker\venv\Lib\site-packages\requests\adapters.py", line 519, in send
    raise ConnectionError(e, request=request)
requests.exceptions.ConnectionError: HTTPSConnectionPool(host='googlechromelabs.github.io', port=443): Max retries exceeded with url: /chrome-for-testing/latest-patch-versions-per-build.json (Caused by NameResolutionError("<urllib3.connection.HTTPSConnection object at 0x00000210139C3090>: Failed to resolve 'googlechromelabs.github.io' ([Errno 11001] getaddrinfo failed)"))

During handling of the above exception, another exception occurred:

Traceback (most recent call last):
  File "C:\Users\Elaman\PycharmProjects\grade_checker\main.py", line 13, in <module>
    mainWindow = Config()
                 ^^^^^^^^
  File "C:\Users\Elaman\PycharmProjects\grade_checker\Config.py", line 28, in __init__
    chrome_install = ChromeDriverManager().install()
                     ^^^^^^^^^^^^^^^^^^^^^^^^^^^^^^^
  File "C:\Users\Elaman\PycharmProjects\grade_checker\venv\Lib\site-packages\webdriver_manager\chrome.py", line 40, in install
    driver_path = self._get_driver_binary_path(self.driver)
                  ^^^^^^^^^^^^^^^^^^^^^^^^^^^^^^^^^^^^^^^^^
  File "C:\Users\Elaman\PycharmProjects\grade_checker\venv\Lib\site-packages\webdriver_manager\core\manager.py", line 35, in _get_driver_binary_path
    binary_path = self._cache_manager.find_driver(driver)
                  ^^^^^^^^^^^^^^^^^^^^^^^^^^^^^^^^^^^^^^^
  File "C:\Users\Elaman\PycharmProjects\grade_checker\venv\Lib\site-packages\webdriver_manager\core\driver_cache.py", line 107, in find_driver
    driver_version = self.get_cache_key_driver_version(driver)
                     ^^^^^^^^^^^^^^^^^^^^^^^^^^^^^^^^^^^^^^^^^
  File "C:\Users\Elaman\PycharmProjects\grade_checker\venv\Lib\site-packages\webdriver_manager\core\driver_cache.py", line 154, in get_cache_key_driver_version
    return driver.get_driver_version_to_download()
           ^^^^^^^^^^^^^^^^^^^^^^^^^^^^^^^^^^^^^^^
  File "C:\Users\Elaman\PycharmProjects\grade_checker\venv\Lib\site-packages\webdriver_manager\core\driver.py", line 48, in get_driver_version_to_download
    return self.get_latest_release_version()
           ^^^^^^^^^^^^^^^^^^^^^^^^^^^^^^^^^
  File "C:\Users\Elaman\PycharmProjects\grade_checker\venv\Lib\site-packages\webdriver_manager\drivers\chrome.py", line 59, in get_latest_release_version
    response = self._http_client.get(url)
               ^^^^^^^^^^^^^^^^^^^^^^^^^^
  File "C:\Users\Elaman\PycharmProjects\grade_checker\venv\Lib\site-packages\webdriver_manager\core\http.py", line 35, in get
    raise exceptions.ConnectionError(f"Could not reach host. Are you offline?")
requests.exceptions.ConnectionError: Could not reach host. Are you offline?
